Node: diffusion_pipeline.preprocessing_stage.mrtrix_5tt
Working directory: /home/localadmin/DATA/ds-sample/derivatives/nipype-1.8.5/sub-01/ses-01/diffusion_pipeline/preprocessing_stage/mrtrix_5tt

Node inputs:

algorithm = freesurfer
args = <undefined>
environ = {}
in_file = <undefined>
out_file = mrtrix_5tt.nii.gz

Traceback (most recent call last):
  File "/opt/anaconda3/envs/cmp_updPack/lib/python3.12/site-packages/nipype/pipeline/plugins/multiproc.py", line 67, in run_node
    result["result"] = node.run(updatehash=updatehash)
                       ^^^^^^^^^^^^^^^^^^^^^^^^^^^^^^^
  File "/opt/anaconda3/envs/cmp_updPack/lib/python3.12/site-packages/nipype/pipeline/engine/nodes.py", line 527, in run
    result = self._run_interface(execute=True)
             ^^^^^^^^^^^^^^^^^^^^^^^^^^^^^^^^^
  File "/opt/anaconda3/envs/cmp_updPack/lib/python3.12/site-packages/nipype/pipeline/engine/nodes.py", line 645, in _run_interface
    return self._run_command(execute)
           ^^^^^^^^^^^^^^^^^^^^^^^^^^
  File "/opt/anaconda3/envs/cmp_updPack/lib/python3.12/site-packages/nipype/pipeline/engine/nodes.py", line 771, in _run_command
    raise NodeExecutionError(msg)
nipype.pipeline.engine.nodes.NodeExecutionError: Exception raised while executing Node mrtrix_5tt.

Cmdline:
	5ttgen freesurfer -nocrop -sgm_amyg_hipp /home/localadmin/DATA/ds-sample/derivatives/cmp-v3.2.0/sub-01/ses-01/anat/sub-01_ses-01_desc-aparcaseg_dseg.nii.gz mrtrix_5tt.nii.gz
Stdout:

Stderr:
	Traceback (most recent call last):
	  File "/opt/anaconda3/envs/cmp_updPack/bin/5ttgen", line 69, in <module>
	    import mrtrix3
	  File "/opt/anaconda3/envs/cmp_updPack/bin/mrtrix3.py", line 17, in <module>
	    import imp, os, sys
	ModuleNotFoundError: No module named 'imp'
Traceback:
	Traceback (most recent call last):
	  File "/opt/anaconda3/envs/cmp_updPack/lib/python3.12/site-packages/nipype/interfaces/base/core.py", line 454, in aggregate_outputs
	    setattr(outputs, key, val)
	  File "/opt/anaconda3/envs/cmp_updPack/lib/python3.12/site-packages/nipype/interfaces/base/traits_extension.py", line 330, in validate
	    value = super(File, self).validate(objekt, name, value, return_pathlike=True)
	            ^^^^^^^^^^^^^^^^^^^^^^^^^^^^^^^^^^^^^^^^^^^^^^^^^^^^^^^^^^^^^^^^^^^^^
	  File "/opt/anaconda3/envs/cmp_updPack/lib/python3.12/site-packages/nipype/interfaces/base/traits_extension.py", line 135, in validate
	    self.error(objekt, name, str(value))
	  File "/opt/anaconda3/envs/cmp_updPack/lib/python3.12/site-packages/traits/base_trait_handler.py", line 74, in error
	    raise TraitError(
	traits.trait_errors.TraitError: The 'out_file' trait of a Generate5ttOutputSpec instance must be a pathlike object or string representing an existing file, but a value of '/home/localadmin/DATA/ds-sample/derivatives/nipype-1.8.5/sub-01/ses-01/diffusion_pipeline/preprocessing_stage/mrtrix_5tt/mrtrix_5tt.nii.gz' <class 'str'> was specified.

	During handling of the above exception, another exception occurred:

	Traceback (most recent call last):
	  File "/opt/anaconda3/envs/cmp_updPack/lib/python3.12/site-packages/nipype/interfaces/base/core.py", line 401, in run
	    outputs = self.aggregate_outputs(runtime)
	              ^^^^^^^^^^^^^^^^^^^^^^^^^^^^^^^
	  File "/opt/anaconda3/envs/cmp_updPack/lib/python3.12/site-packages/nipype/interfaces/base/core.py", line 461, in aggregate_outputs
	    raise FileNotFoundError(msg)
	FileNotFoundError: No such file or directory '/home/localadmin/DATA/ds-sample/derivatives/nipype-1.8.5/sub-01/ses-01/diffusion_pipeline/preprocessing_stage/mrtrix_5tt/mrtrix_5tt.nii.gz' for output 'out_file' of a Generate5tt interface

